.../Download/Botia $ python botia.py            Traceback (most recent call last):                File "/data/data/com.termux/files/usr/lib/python3.12/site-packages/sqlalchemy/engine/base.py", line 2228, in _wrap_pool_connect
    return fn()
           ^^^^
  File "/data/data/com.termux/files/usr/lib/python3.12/site-packages/sqlalchemy/pool.py", line 434, in connect
    return _ConnectionFairy._checkout(self)
           ^^^^^^^^^^^^^^^^^^^^^^^^^^^^^^^^
  File "/data/data/com.termux/files/usr/lib/python3.12/site-packages/sqlalchemy/pool.py", line 831, in _checkout
    fairy = _ConnectionRecord.checkout(pool)
            ^^^^^^^^^^^^^^^^^^^^^^^^^^^^^^^^
  File "/data/data/com.termux/files/usr/lib/python3.12/site-packages/sqlalchemy/pool.py", line 563, in checkout
    rec = pool._do_get()
          ^^^^^^^^^^^^^^
  File "/data/data/com.termux/files/usr/lib/python3.12/site-packages/sqlalchemy/pool.py", line 1355, in _do_get
    return self._create_connection()
           ^^^^^^^^^^^^^^^^^^^^^^^^^
  File "/data/data/com.termux/files/usr/lib/python3.12/site-packages/sqlalchemy/pool.py", line 379, in _create_connection
    return _ConnectionRecord(self)
           ^^^^^^^^^^^^^^^^^^^^^^^
  File "/data/data/com.termux/files/usr/lib/python3.12/site-packages/sqlalchemy/pool.py", line 508, in __init__
    self.__connect(first_connect_check=True)
  File "/data/data/com.termux/files/usr/lib/python3.12/site-packages/sqlalchemy/pool.py", line 710, in __connect
    connection = pool._invoke_creator(self)
                 ^^^^^^^^^^^^^^^^^^^^^^^^^^
  File "/data/data/com.termux/files/usr/lib/python3.12/site-packages/sqlalchemy/engine/strategies.py", line 114, in connect
    return dialect.connect(*cargs, **cparams)
           ^^^^^^^^^^^^^^^^^^^^^^^^^^^^^^^^^^
  File "/data/data/com.termux/files/usr/lib/python3.12/site-packages/sqlalchemy/engine/default.py", line 437, in connect
    return self.dbapi.connect(*cargs, **cparams)
           ^^^^^^^^^^^^^^^^^^^^^^^^^^^^^^^^^^^^^
sqlite3.OperationalError: unable to open database file

The above exception was the direct cause of the following exception:

Traceback (most recent call last):
  File "/storage/emulated/0/Download/Botia/botia.py", line 11, in <module>
    from dadosite.tdc import process_message
  File "/storage/emulated/0/Download/Botia/dadosite/tdc.py", line 26, in <module>
    chatbot = ChatBot(
              ^^^^^^^^
  File "/data/data/com.termux/files/usr/lib/python3.12/site-packages/chatterbot/chatterbot.py", line 34, in __init__
    self.storage = utils.initialize_class(storage_adapter, **kwargs)
                   ^^^^^^^^^^^^^^^^^^^^^^^^^^^^^^^^^^^^^^^^^^^^^^^^^
  File "/data/data/com.termux/files/usr/lib/python3.12/site-packages/chatterbot/utils.py", line 54, in initialize_class
    return Class(*args, **kwargs)
           ^^^^^^^^^^^^^^^^^^^^^^
  File "/data/data/com.termux/files/usr/lib/python3.12/site-packages/chatterbot/storage/sql_storage.py", line 46, in __init__
    if not self.engine.dialect.has_table(self.engine, 'Statement'):
           ^^^^^^^^^^^^^^^^^^^^^^^^^^^^^^^^^^^^^^^^^^^^^^^^^^^^^^^
  File "/data/data/com.termux/files/usr/lib/python3.12/site-packages/sqlalchemy/dialects/sqlite/base.py", line 1356, in has_table
    info = self._get_table_pragma(
           ^^^^^^^^^^^^^^^^^^^^^^^
  File "/data/data/com.termux/files/usr/lib/python3.12/site-packages/sqlalchemy/dialects/sqlite/base.py", line 1799, in _get_table_pragma
    cursor = connection.execute(statement)
             ^^^^^^^^^^^^^^^^^^^^^^^^^^^^^
  File "/data/data/com.termux/files/usr/lib/python3.12/site-packages/sqlalchemy/engine/base.py", line 2143, in execute
    connection = self.contextual_connect(close_with_result=True)
                 ^^^^^^^^^^^^^^^^^^^^^^^^^^^^^^^^^^^^^^^^^^^^^^^
  File "/data/data/com.termux/files/usr/lib/python3.12/site-packages/sqlalchemy/engine/base.py", line 2192, in contextual_connect
    self._wrap_pool_connect(self.pool.connect, None),
    ^^^^^^^^^^^^^^^^^^^^^^^^^^^^^^^^^^^^^^^^^^^^^^^^
  File "/data/data/com.termux/files/usr/lib/python3.12/site-packages/sqlalchemy/engine/base.py", line 2231, in _wrap_pool_connect
    Connection._handle_dbapi_exception_noconnection(
  File "/data/data/com.termux/files/usr/lib/python3.12/site-packages/sqlalchemy/engine/base.py", line 1528, in _handle_dbapi_exception_noconnection
    util.raise_from_cause(sqlalchemy_exception, exc_info)
  File "/data/data/com.termux/files/usr/lib/python3.12/site-packages/sqlalchemy/util/compat.py", line 296, in raise_from_cause
    reraise(type(exception), exception, tb=exc_tb, cause=cause)
  File "/data/data/com.termux/files/usr/lib/python3.12/site-packages/sqlalchemy/util/compat.py", line 276, in reraise
    raise value.with_traceback(tb)
  File "/data/data/com.termux/files/usr/lib/python3.12/site-packages/sqlalchemy/engine/base.py", line 2228, in _wrap_pool_connect
    return fn()
           ^^^^
  File "/data/data/com.termux/files/usr/lib/python3.12/site-packages/sqlalchemy/pool.py", line 434, in connect
    return _ConnectionFairy._checkout(self)
           ^^^^^^^^^^^^^^^^^^^^^^^^^^^^^^^^
  File "/data/data/com.termux/files/usr/lib/python3.12/site-packages/sqlalchemy/pool.py", line 831, in _checkout
    fairy = _ConnectionRecord.checkout(pool)
            ^^^^^^^^^^^^^^^^^^^^^^^^^^^^^^^^
  File "/data/data/com.termux/files/usr/lib/python3.12/site-packages/sqlalchemy/pool.py", line 563, in checkout
    rec = pool._do_get()
          ^^^^^^^^^^^^^^
  File "/data/data/com.termux/files/usr/lib/python3.12/site-packages/sqlalchemy/pool.py", line 1355, in _do_get
    return self._create_connection()
           ^^^^^^^^^^^^^^^^^^^^^^^^^
  File "/data/data/com.termux/files/usr/lib/python3.12/site-packages/sqlalchemy/pool.py", line 379, in _create_connection
    return _ConnectionRecord(self)
           ^^^^^^^^^^^^^^^^^^^^^^^
  File "/data/data/com.termux/files/usr/lib/python3.12/site-packages/sqlalchemy/pool.py", line 508, in __init__
    self.__connect(first_connect_check=True)
  File "/data/data/com.termux/files/usr/lib/python3.12/site-packages/sqlalchemy/pool.py", line 710, in __connect
    connection = pool._invoke_creator(self)
                 ^^^^^^^^^^^^^^^^^^^^^^^^^^
  File "/data/data/com.termux/files/usr/lib/python3.12/site-packages/sqlalchemy/engine/strategies.py", line 114, in connect
    return dialect.connect(*cargs, **cparams)
           ^^^^^^^^^^^^^^^^^^^^^^^^^^^^^^^^^^
  File "/data/data/com.termux/files/usr/lib/python3.12/site-packages/sqlalchemy/engine/default.py", line 437, in connect
    return self.dbapi.connect(*cargs, **cparams)
           ^^^^^^^^^^^^^^^^^^^^^^^^^^^^^^^^^^^^^
sqlalchemy.exc.OperationalError: (sqlite3.OperationalError) unable to open database file (Background on this error at: http://sqlalche.me/e/e3q8)